2021-05-13 22:25:54,002 INFO    MainThread:14372 [wandb_setup.py:_flush():69] setting env: {}
2021-05-13 22:25:54,002 INFO    MainThread:14372 [wandb_setup.py:_flush():69] setting login settings: {}
2021-05-13 22:25:54,002 INFO    MainThread:14372 [wandb_init.py:_log_setup():336] Logging user logs to C:\Users\harry\PycharmProjects\Neural-Networks-Assignment\wandb\run-20210513_222554-1n9g9yw9\logs\debug.log
2021-05-13 22:25:54,002 INFO    MainThread:14372 [wandb_init.py:_log_setup():337] Logging internal logs to C:\Users\harry\PycharmProjects\Neural-Networks-Assignment\wandb\run-20210513_222554-1n9g9yw9\logs\debug-internal.log
2021-05-13 22:25:54,002 INFO    MainThread:14372 [wandb_init.py:init():369] calling init triggers
2021-05-13 22:25:54,002 INFO    MainThread:14372 [wandb_init.py:init():374] wandb.init called with sweep_config: {}
config: {}
2021-05-13 22:25:54,002 INFO    MainThread:14372 [wandb_init.py:init():418] starting backend
2021-05-13 22:25:54,002 INFO    MainThread:14372 [backend.py:_multiprocessing_setup():69] multiprocessing start_methods=spawn, using: spawn
2021-05-13 22:25:54,002 INFO    MainThread:14372 [backend.py:ensure_launched():123] starting backend process...
2021-05-13 22:25:54,326 INFO    MainThread:14372 [backend.py:ensure_launched():127] started backend process with pid: 21296
2021-05-13 22:25:54,326 INFO    MainThread:14372 [wandb_init.py:init():423] backend started and connected
2021-05-13 22:25:54,326 INFO    MainThread:14372 [wandb_init.py:init():463] updated telemetry
2021-05-13 22:25:54,326 INFO    MainThread:14372 [wandb_init.py:init():482] communicating current version
2021-05-13 22:25:59,337 INFO    MainThread:14372 [wandb_init.py:init():495] communicating run to backend with 30 second timeout
2021-05-13 22:26:12,276 ERROR   Thread-7  :14372 [retry.py:__call__():111] Retry attempt failed:
Traceback (most recent call last):
  File "C:\Users\harry\Anaconda3\envs\ML38\lib\site-packages\urllib3\connection.py", line 169, in _new_conn
    conn = connection.create_connection(
  File "C:\Users\harry\Anaconda3\envs\ML38\lib\site-packages\urllib3\util\connection.py", line 73, in create_connection
    for res in socket.getaddrinfo(host, port, family, socket.SOCK_STREAM):
  File "C:\Users\harry\Anaconda3\envs\ML38\lib\socket.py", line 918, in getaddrinfo
    for res in _socket.getaddrinfo(host, port, family, type, proto, flags):
socket.gaierror: [Errno 11001] getaddrinfo failed

During handling of the above exception, another exception occurred:

Traceback (most recent call last):
  File "C:\Users\harry\Anaconda3\envs\ML38\lib\site-packages\urllib3\connectionpool.py", line 699, in urlopen
    httplib_response = self._make_request(
  File "C:\Users\harry\Anaconda3\envs\ML38\lib\site-packages\urllib3\connectionpool.py", line 382, in _make_request
    self._validate_conn(conn)
  File "C:\Users\harry\Anaconda3\envs\ML38\lib\site-packages\urllib3\connectionpool.py", line 1010, in _validate_conn
    conn.connect()
  File "C:\Users\harry\Anaconda3\envs\ML38\lib\site-packages\urllib3\connection.py", line 353, in connect
    conn = self._new_conn()
  File "C:\Users\harry\Anaconda3\envs\ML38\lib\site-packages\urllib3\connection.py", line 181, in _new_conn
    raise NewConnectionError(
urllib3.exceptions.NewConnectionError: <urllib3.connection.HTTPSConnection object at 0x000001908AB533D0>: Failed to establish a new connection: [Errno 11001] getaddrinfo failed

During handling of the above exception, another exception occurred:

Traceback (most recent call last):
  File "C:\Users\harry\Anaconda3\envs\ML38\lib\site-packages\requests\adapters.py", line 439, in send
    resp = conn.urlopen(
  File "C:\Users\harry\Anaconda3\envs\ML38\lib\site-packages\urllib3\connectionpool.py", line 755, in urlopen
    retries = retries.increment(
  File "C:\Users\harry\Anaconda3\envs\ML38\lib\site-packages\urllib3\util\retry.py", line 573, in increment
    raise MaxRetryError(_pool, url, error or ResponseError(cause))
urllib3.exceptions.MaxRetryError: HTTPSConnectionPool(host='api.wandb.ai', port=443): Max retries exceeded with url: /graphql (Caused by NewConnectionError('<urllib3.connection.HTTPSConnection object at 0x000001908AB533D0>: Failed to establish a new connection: [Errno 11001] getaddrinfo failed'))

During handling of the above exception, another exception occurred:

Traceback (most recent call last):
  File "C:\Users\harry\Anaconda3\envs\ML38\lib\site-packages\wandb\old\retry.py", line 96, in __call__
    result = self._call_fn(*args, **kwargs)
  File "C:\Users\harry\Anaconda3\envs\ML38\lib\site-packages\wandb\sdk\internal\internal_api.py", line 123, in execute
    return self.client.execute(*args, **kwargs)
  File "C:\Users\harry\Anaconda3\envs\ML38\lib\site-packages\wandb\vendor\gql-0.2.0\gql\client.py", line 52, in execute
    result = self._get_result(document, *args, **kwargs)
  File "C:\Users\harry\Anaconda3\envs\ML38\lib\site-packages\wandb\vendor\gql-0.2.0\gql\client.py", line 60, in _get_result
    return self.transport.execute(document, *args, **kwargs)
  File "C:\Users\harry\Anaconda3\envs\ML38\lib\site-packages\wandb\vendor\gql-0.2.0\gql\transport\requests.py", line 38, in execute
    request = requests.post(self.url, **post_args)
  File "C:\Users\harry\Anaconda3\envs\ML38\lib\site-packages\requests\api.py", line 119, in post
    return request('post', url, data=data, json=json, **kwargs)
  File "C:\Users\harry\Anaconda3\envs\ML38\lib\site-packages\requests\api.py", line 61, in request
    return session.request(method=method, url=url, **kwargs)
  File "C:\Users\harry\Anaconda3\envs\ML38\lib\site-packages\requests\sessions.py", line 542, in request
    resp = self.send(prep, **send_kwargs)
  File "C:\Users\harry\Anaconda3\envs\ML38\lib\site-packages\requests\sessions.py", line 655, in send
    r = adapter.send(request, **kwargs)
  File "C:\Users\harry\Anaconda3\envs\ML38\lib\site-packages\requests\adapters.py", line 516, in send
    raise ConnectionError(e, request=request)
requests.exceptions.ConnectionError: HTTPSConnectionPool(host='api.wandb.ai', port=443): Max retries exceeded with url: /graphql (Caused by NewConnectionError('<urllib3.connection.HTTPSConnection object at 0x000001908AB533D0>: Failed to establish a new connection: [Errno 11001] getaddrinfo failed'))
2021-05-13 22:26:29,342 INFO    MainThread:14372 [interface.py:_communicate_run():636] couldn't get run from backend
2021-05-13 22:26:29,342 ERROR   MainThread:14372 [wandb_init.py:init():499] backend process timed out
2021-05-13 22:26:29,342 ERROR   MainThread:14372 [wandb_init.py:init():508] encountered error: Error communicating with wandb process
try: wandb.init(settings=wandb.Settings(start_method='fork'))
or:  wandb.init(settings=wandb.Settings(start_method='thread'))
For more info see: https://docs.wandb.ai/library/init#init-start-error
2021-05-13 22:26:39,607 INFO    MainThread:14372 [wandb_init.py:teardown():187] tearing down wandb.init
