2021-05-13 22:25:55,206 INFO    MainThread:21296 [internal.py:wandb_internal():88] W&B internal server running at pid: 21296, started at: 2021-05-13 22:25:55.190784
2021-05-13 22:25:55,206 INFO    WriterThread:21296 [datastore.py:open_for_write():77] open: C:\Users\harry\PycharmProjects\Neural-Networks-Assignment\wandb\run-20210513_222554-1n9g9yw9\run-1n9g9yw9.wandb
2021-05-13 22:25:55,206 DEBUG   HandlerThread:21296 [handler.py:handle_request():120] handle_request: check_version
2021-05-13 22:25:55,206 DEBUG   SenderThread:21296 [sender.py:send():160] send: header
2021-05-13 22:25:55,206 DEBUG   SenderThread:21296 [sender.py:send():160] send: request
2021-05-13 22:25:55,206 DEBUG   SenderThread:21296 [sender.py:send_request():169] send_request: check_version
2021-05-13 22:26:00,210 DEBUG   SenderThread:21296 [sender.py:send():160] send: run
2021-05-13 22:26:13,896 ERROR   SenderThread:21296 [retry.py:__call__():111] Retry attempt failed:
Traceback (most recent call last):
  File "C:\Users\harry\Anaconda3\envs\ML38\lib\site-packages\urllib3\connection.py", line 169, in _new_conn
    conn = connection.create_connection(
  File "C:\Users\harry\Anaconda3\envs\ML38\lib\site-packages\urllib3\util\connection.py", line 73, in create_connection
    for res in socket.getaddrinfo(host, port, family, socket.SOCK_STREAM):
  File "C:\Users\harry\Anaconda3\envs\ML38\lib\socket.py", line 918, in getaddrinfo
    for res in _socket.getaddrinfo(host, port, family, type, proto, flags):
socket.gaierror: [Errno 11001] getaddrinfo failed

During handling of the above exception, another exception occurred:

Traceback (most recent call last):
  File "C:\Users\harry\Anaconda3\envs\ML38\lib\site-packages\urllib3\connectionpool.py", line 699, in urlopen
    httplib_response = self._make_request(
  File "C:\Users\harry\Anaconda3\envs\ML38\lib\site-packages\urllib3\connectionpool.py", line 382, in _make_request
    self._validate_conn(conn)
  File "C:\Users\harry\Anaconda3\envs\ML38\lib\site-packages\urllib3\connectionpool.py", line 1010, in _validate_conn
    conn.connect()
  File "C:\Users\harry\Anaconda3\envs\ML38\lib\site-packages\urllib3\connection.py", line 353, in connect
    conn = self._new_conn()
  File "C:\Users\harry\Anaconda3\envs\ML38\lib\site-packages\urllib3\connection.py", line 181, in _new_conn
    raise NewConnectionError(
urllib3.exceptions.NewConnectionError: <urllib3.connection.HTTPSConnection object at 0x000002BAC0F64D00>: Failed to establish a new connection: [Errno 11001] getaddrinfo failed

During handling of the above exception, another exception occurred:

Traceback (most recent call last):
  File "C:\Users\harry\Anaconda3\envs\ML38\lib\site-packages\requests\adapters.py", line 439, in send
    resp = conn.urlopen(
  File "C:\Users\harry\Anaconda3\envs\ML38\lib\site-packages\urllib3\connectionpool.py", line 755, in urlopen
    retries = retries.increment(
  File "C:\Users\harry\Anaconda3\envs\ML38\lib\site-packages\urllib3\util\retry.py", line 573, in increment
    raise MaxRetryError(_pool, url, error or ResponseError(cause))
urllib3.exceptions.MaxRetryError: HTTPSConnectionPool(host='api.wandb.ai', port=443): Max retries exceeded with url: /graphql (Caused by NewConnectionError('<urllib3.connection.HTTPSConnection object at 0x000002BAC0F64D00>: Failed to establish a new connection: [Errno 11001] getaddrinfo failed'))

During handling of the above exception, another exception occurred:

Traceback (most recent call last):
  File "C:\Users\harry\Anaconda3\envs\ML38\lib\site-packages\wandb\old\retry.py", line 96, in __call__
    result = self._call_fn(*args, **kwargs)
  File "C:\Users\harry\Anaconda3\envs\ML38\lib\site-packages\wandb\sdk\internal\internal_api.py", line 123, in execute
    return self.client.execute(*args, **kwargs)
  File "C:\Users\harry\Anaconda3\envs\ML38\lib\site-packages\wandb\vendor\gql-0.2.0\gql\client.py", line 52, in execute
    result = self._get_result(document, *args, **kwargs)
  File "C:\Users\harry\Anaconda3\envs\ML38\lib\site-packages\wandb\vendor\gql-0.2.0\gql\client.py", line 60, in _get_result
    return self.transport.execute(document, *args, **kwargs)
  File "C:\Users\harry\Anaconda3\envs\ML38\lib\site-packages\wandb\vendor\gql-0.2.0\gql\transport\requests.py", line 38, in execute
    request = requests.post(self.url, **post_args)
  File "C:\Users\harry\Anaconda3\envs\ML38\lib\site-packages\requests\api.py", line 119, in post
    return request('post', url, data=data, json=json, **kwargs)
  File "C:\Users\harry\Anaconda3\envs\ML38\lib\site-packages\requests\api.py", line 61, in request
    return session.request(method=method, url=url, **kwargs)
  File "C:\Users\harry\Anaconda3\envs\ML38\lib\site-packages\requests\sessions.py", line 542, in request
    resp = self.send(prep, **send_kwargs)
  File "C:\Users\harry\Anaconda3\envs\ML38\lib\site-packages\requests\sessions.py", line 655, in send
    r = adapter.send(request, **kwargs)
  File "C:\Users\harry\Anaconda3\envs\ML38\lib\site-packages\requests\adapters.py", line 516, in send
    raise ConnectionError(e, request=request)
requests.exceptions.ConnectionError: HTTPSConnectionPool(host='api.wandb.ai', port=443): Max retries exceeded with url: /graphql (Caused by NewConnectionError('<urllib3.connection.HTTPSConnection object at 0x000002BAC0F64D00>: Failed to establish a new connection: [Errno 11001] getaddrinfo failed'))
2021-05-13 22:26:29,343 DEBUG   HandlerThread:21296 [handler.py:handle_request():120] handle_request: shutdown
2021-05-13 22:26:29,343 INFO    HandlerThread:21296 [handler.py:finish():624] shutting down handler
2021-05-13 22:26:29,589 INFO    WriterThread:21296 [datastore.py:close():258] close: C:\Users\harry\PycharmProjects\Neural-Networks-Assignment\wandb\run-20210513_222554-1n9g9yw9\run-1n9g9yw9.wandb
2021-05-13 22:26:37,284 INFO    SenderThread:21296 [sender.py:_start_run_threads():651] run started: 1n9g9yw9 with start time 1620941154
2021-05-13 22:26:37,284 INFO    SenderThread:21296 [sender.py:finish():884] shutting down sender
2021-05-13 22:26:39,476 INFO    MainThread:21296 [internal.py:handle_exit():78] Internal process exited
